[ERROR:flask.app: Exception on /api/classify [POST] in 2019-01-20 17:57:44,198; app.py:1761
Traceback (most recent call last):
  File "D:\Projects\CNN\venv\lib\site-packages\flask\app.py", line 2292, in wsgi_app
    response = self.full_dispatch_request()
  File "D:\Projects\CNN\venv\lib\site-packages\flask\app.py", line 1815, in full_dispatch_request
    rv = self.handle_user_exception(e)
  File "D:\Projects\CNN\venv\lib\site-packages\flask_cors\extension.py", line 161, in wrapped_function
    return cors_after_request(app.make_response(f(*args, **kwargs)))
  File "D:\Projects\CNN\venv\lib\site-packages\flask\app.py", line 1718, in handle_user_exception
    reraise(exc_type, exc_value, tb)
  File "D:\Projects\CNN\venv\lib\site-packages\flask\_compat.py", line 35, in reraise
    raise value
  File "D:\Projects\CNN\venv\lib\site-packages\flask\app.py", line 1813, in full_dispatch_request
    rv = self.dispatch_request()
  File "D:\Projects\CNN\venv\lib\site-packages\flask\app.py", line 1799, in dispatch_request
    return self.view_functions[rule.endpoint](**req.view_args)
  File "server.py", line 97, in classify
    data = data.reshape(IMG_SIZE, IMG_SIZE, 1)
ValueError: cannot reshape array of size 7500 into shape (50,50,1)
